Workbook

Sheet IDX
A1: Field Check Tables
A2: Contents | C2: Instructions
C3: The Field Check Tables are run in SPSS using the 'MICS7 - ALLFCT.sps' syntax. Please read comments and further instructions in the 'targets.sps' syntax. Customise as described. The Overview sheet presents data divided in periods of fieldwork to allow comparison of performance over time. The Figures sheet presents age graphs. All following sheets detail a variety of quality checks.
A4: ='Overview 1'!A1 -> Performance overview 1
A5: Performance overview 2
A6: ='F1'!A1:L1 -> F1. Household response rate
A7: =F2W!A1 -> F2W. Eligible women per household
A8: =F2M!$A$1 -> F2M. Eligible men per household
A9: =F2UC!A1 -> F2UC. Eligible children per household
A10: =F3W!$A$1 -> F3W. Response rate: Eligible women
A11: =F3M!$A$1 -> F3M. Response rate: Eligible men | C11: Important note: Field Check Tables should be produced approximately every week and a final set should be produced at the end of fieldwork. This final and comprehensive set will be incredibly valuable to the next similar survey and contains performance information on individuals, that can guide recruitment and targeted training. Please therefore make sure to include not only team level information in this final set.
A12: =F3U!A1 -> F3U. Response rate: Under 5
A13: =F3C!A1 -> F3C. Response rate: 5-17
A14: =F3C2!A1 -> F3C2. Response rate: 7-14
A15: =F3Q!A1 -> F3Q. Response rate: Water Quality Testing
A16: =F4W!$A$1 -> F4W. Age distribution of women interviewed
A17: =F4M!$A$1 -> F4M. Age distribution of men interviewed
A18: =F5W!$A$1 -> F5W. Age displacement: women
A19: =F5M!$A$1 -> F5M. Age displacement: men
A20: =F5UC!$A$1 -> F5UC. Age displacement: young children
A21: =F6W!$A$1 -> F6W. Birth date reporting: Women
A22: =F6W2!$A$1 -> F6W2. Birth date reporting: Women
A23: =F6M!$A$1 -> F6M. Birth date reporting: Men
A24: =F6U!$A$1 -> F6U. Birth date reporting: Children under-5
A25: =F6C!$A$1 -> F6C. Birth date reporting: Children, adolescents and young people
A26: =F6B!$A$1 -> F6B. Birth date reporting: First and last births
A27: =F7W!$A$1 -> F7W. Question responses by team: Women's questionnaire
A28: =F7M!$A$1 -> F7M. Question responses by team: Men's questionnaire
A29: =F7U!$A$1 -> F7U. Question responses by team: Under-5 questionnaire
A30: =F7C!A1 -> F7C. Question responses by team: 5-17 questionnaire
A31: =F8A!$A$1 -> F8A: Observation of birth certificates
A32: =F8B!$A$1 -> F8B. Observation of vaccination cards
A33: =F8C!$A$1 -> F8C. Observation of women's health cards
A34: =F8D!$A$1 -> F8D. Observation of bednets
A35: =F8E!A1 -> F8E. Observation of places for hand washing
A36: =F8Q!A1 -> F8Q. Observation and collection of water quality samples
A37: =F9A!$A$1 -> F9A. Height and weight of children (age 0-4)
A38: =F9B!$A$1 -> F9B. Heaping in anthropometric measurements (age 0-4)
A39: =F9C!$A$1 -> F9C. Height and weight of children (age 5-9)
A40: =F9D!$A$1 -> F9D. Heaping in anthropometric measurements (age 5-9)
...

Sheet Overview 1
A1: Performance overview 1
A2: Performance indicators sectioned in periods of fieldwork, by interviewer team, Survey name, Year
B3: Mean number of household members | H3: Percentage of closed clusters with at least one HL reinterview | J3: Total number of clusters closed | L3: Children ever born - Mean number | O3: Anthropometric measurements - Percentage height/weight out of range | R3: Blank testing - Percentage of tests with e.coli presence
B4: First half of fieldwork to date | E4: Second half of fieldwork to date | H4: First half of fieldwork to date | I4: Second half of fieldwork to date | L4: First half of fieldwork to date | M4: Second half of fieldwork to date | O4: First half of fieldwork to date | P4: Second half of fieldwork to date | R4: First half of fieldwork to date | S4: Second half of fieldwork to date
B5: Urban | C5: Rural | E5: Urban | F5: Rural
A7: Total
A9: Team
A10: Team 1
A11: Team 2
A12: Team 3
A13: Team 4
A14: Team 5
A16: The values calculated for columns of first and second half of fieldwork are done computed individually for each team and for the total by splitting the number of observations in half, not number of days in the field to date.

Sheet Overview 2
A1: Performance overview 2
A2: Performance indicators sectioned in periods of fieldwork, by interviewer team, Survey name, Year
B3: Female age ratios | P3: Male age ratios
B4: First half of fieldwork to date | I4: Second half of fieldwork to date | P4: First half of fieldwork to date | W4: Second half of fieldwork to date
B5: 2/1 | C5: 5/4 | D5: 6/7 | E5: 14/15 | F5: 25/24 | G5: 50/49 | I5: 2/1 | J5: 5/4 | K5: 6/7 | L5: 14/15 | M5: 25/24 | N5: 50/49 | P5: 2/1 | Q5: 5/4 | R5: 6/7 | S5: 14/15 | T5: 25/24 | U5: 50/49 | W5: 2/1 | X5: 5/4 | Y5: 6/7 | Z5: 14/15 | AA5: 25/24 | AB5: 50/49
A7: Total
A9: Team
A10: Team 1
A11: Team 2
A12: Team 3
A13: Team 4
A14: Team 5
A16: The values calculated for columns of first and second half of fieldwork are done computed individually for each team and for the total by splitting the number of observations in half, not number of days in the field to date.

Sheet F1
A1: F1. Household response rate
A2: Percent distribution of sampled households by result of household interview, according to interviewer team, Survey name, Year
B3: Result of household interview | J3: Total | K3: Number of households | L3: Household response rate (%) (1) / (1+2+4+7) * 100
B4: Completed | C4: No household member or no competent respondent at home at time of visit | D4: Entire household absent for extended period of time | E4: Refused | F4: Dwelling vacant/ Address not a dwelling | G4: Dwelling destroyed | H4: Dwelling not found | I4: Other
B5: (1) | C5: (2) | D5: (3) | E5: (4) | F5: (5) | G5: (6) | H5: (7) | I5: (96)
A7: Total | J7: 100
A9: Team
A10: Team 1 | J10: 100
A11: Team 2 | J11: 100
A12: Team 3 | J12: 100
A13: Team 4 | J13: 100
A14: Team 5 | J14: 100

Sheet F2W
A1: F2W. Eligible women per household
A2: Mean number of eligible women age 15-49 years per household, according to interviewer team, Survey name, Year
B3: Urban | G3: Rural
B4: Number of completed households | C4: Number of eligible women in completed households | D4: Mean number of eligible women per household | E4: Target not met | G4: Number of completed households | H4: Number of eligible women in completed households | I4: Mean number of eligible women per household | J4: Target not met
A6: Total
A8: Team
A9: Team 1
A10: Team 2
A11: Team 3
A12: Team 4
A13: Team 5

Sheet F2M
A1: F2M. Eligible men per household
A2: Mean number of eligible men age 15-49 years per household, according to interviewer team, Survey name, Year
B3: Urban | I3: Rural
B4: Number of completed households | C4: Number of completed households selected for men's interviews | D4: Number of eligible men in selected and completed households | E4: Mean number of eligible men per household not selected | F4: Mean number of eligible men per selected household | G4: Target not met | I4: Number of completed households | J4: Number of completed households selected for men's interviews | K4: Number of eligible men in selected and completed households | L4: Mean number of eligible men per household not selected | M4: Mean number of eligible men per selected household | N4: Target not met
A6: Total
A8: Team
A9: Team 1
A10: Team 2
A11: Team 3
A12: Team 4
A13: Team 5

Sheet F2UC
A1: F2UC. Eligible children per household
A2: Mean number of eligible children per household, according to interviewer team and percentage of households with at least one child age 5-17 years, Survey name, Year
B3: Urban | L3: Rural
B4: Eligible children in completed households | H4: Percentage of households with at least one eligible child age 5-17 years | I4: Target not met | J4: Number of completed households | L4: Eligible children in completed households | R4: Percentage of households with at least one eligible child age 5-17 years | S4: Target not met | T4: Number of completed households
B5: Under 5 | F5: 5-17 | L5: Under 5 | P5: 5-17
B6: Number | C6: Mean | D6: Target not met | F6: Number | G6: Mean | L6: Number | M6: Mean | N6: Target not met | P6: Number | Q6: Mean
A8: Total
A10: Team
A11: Team 1
A12: Team 2
A13: Team 3
A14: Team 4
A15: Team 5

Sheet F3W
A1: F3W. Response rate: Eligible women
A2: Percent distribution of eligible women age 15-49 years by result of individual interview, according to interviewer team, Survey name, Year
B3: Result of individual interview (Women's Questionnaire) | I3: Total | J3: Number of women | K3: Percentage with no adult consent | L3: Number of women age 15-17 years
B4: Completed | C4: Not at home | D4: Refused | E4: Partly completed | F4: Incapacitated | G4: No adult consent | H4: Other
B5: (01) | C5: (02) | D5: (03) | E5: (04) | F5: (06) | G5: (06) | H5: (96)
A7: Total | I7: 100
A9: Team
A10: Team 1 | I10: 100
A11: Team 2 | I11: 100
A12: Team 3 | I12: 100
A13: Team 4 | I13: 100
A14: Team 5 | I14: 100

Sheet F3M
A1: F3M. Response rate: Eligible men
A2: Percent distribution of eligible men age 15-49 years by result of individual interview, according to interviewer team, Survey name, Year
B3: Result of individual interview (Men's Questionnaire) | H3: Total | I3: Number of men | J3: Percentage with no adult consent | K3: Number of men age 15-17 years
B4: Completed | C4: Not at home | D4: Refused | E4: Partly completed | F4: Incapacitated | G4: Other
B5: (1) | C5: (2) | D5: (3) | E5: (4) | F5: (5) | G5: (96)
A7: Total | H7: 100
A9: Team
A10: Team 1 | H10: 100
A11: Team 2 | H11: 100
A12: Team 3 | H12: 100
A13: Team 4 | H13: 100
A14: Team 5 | H14: 100

Sheet F3U
A1: F3U. Response rate: Under 5
A2: Percent distribution of eligible children under age 5 by result of individual interview with mother/caretaker, according to interviewer team, Survey name, Year
B3: Result of individual interview (Under-5 Questionnaire) | I3: Total | J3: Number of children | K3: Percentage with no adult consent | L3: Number of mother/caretakers age 15-17 years
B4: Completed | C4: Not at home | D4: Refused | E4: Partly completed | F4: Incapacitated | G4: No adult consent | H4: Other
B5: (01) | C5: (02) | D5: (03) | E5: (04) | F5: (05) | G5: (06) | H5: (96)
A7: Total | I7: 100
A9: Team
A10: Team 1 | I10: 100
A11: Team 2 | I11: 100
A12: Team 3 | I12: 100
A13: Team 4 | I13: 100
A14: Team 5 | I14: 100

Sheet F3C
A1: F3C. Response rate: 5-17
A2: Percent distribution of selected children age 5-17 by result of individual interview with mother/caretaker, according to interviewer team, Survey name, Year
B3: Result of individual interview (5-17 Questionnaire) | I3: Total | J3: Number of children | K3: Percentage with no adult consent | L3: Percentage emancipated children | M3: Number of selected children age 15-17 years
B4: Completed | C4: Not at home | D4: Refused | E4: Partly completed | F4: Incapacitated | G4: No adult consent | H4: Other
B5: (01) | C5: (02) | D5: (03) | E5: (04) | F5: (05) | G5: (06) | H5: (96)
A7: Total | I7: 100
A9: Team
A10: Team 1 | I10: 100
A11: Team 2 | I11: 100
A12: Team 3 | I12: 100
A13: Team 4 | I13: 100
A14: Team 5 | I14: 100

Sheet F3C2
A1: F3C2. Response rate: 7-14
A2: Percent distribution of selected children age 7-14 by result of learning assessment, according to interviewer team, Survey name, Year
B3: Result of learning assessment (age 7-14 in 5-17 Questionnaire) | I3: Total | J3: Number of children
B4: Completed | C4: Not at home | D4: Mother/Caretaker refused | E4: Child refused | F4: Partly completed | G4: Incapacitated | H4: Other
B5: (01) | C5: (02) | D5: (03) | E5: (04) | F5: (05) | G5: (06) | H5: (96)
A7: Total | I7: 100
A9: Team
A10: Team 1 | I10: 100
A11: Team 2 | I11: 100
A12: Team 3 | I12: 100
A13: Team 4 | I13: 100
A14: Team 5 | I14: 100

Sheet F3Q
A1: F3Q. Response rate: Water Quality Testing
A2: Percent distribution of selected households by result of water quality testing, according to interviewer team, Survey name, Year
A3: Team | B3: Result of water quality testing (Water Quality Testing Questionnaire) | G3: Total | H3: Number of households selected
B4: Completed | C4: Permission not given | D4: Glass of water not given | E4: Partly completed | F4: Other
B5: (01) | C5: (02) | D5: (03) | E5: (04) | F5: (96)
A7: Total | G7: 100
A9: Team
A10: Team 1 | G10: 100
A11: Team 2 | G11: 100
A12: Team 3 | G12: 100
A13: Team 4 | G13: 100
A14: Team 5 | G14: 100

Sheet F4W
A1: F4W. Age distribution of women interviewed
A2: Number of women age 15-49 years listed in the household schedule and proportion successfully interviewed by age group, according to interviewer team, Survey name, Year
C3: Women's age (15-49 years) | J3: Total | K3: Minimum percentage interviewed in any age group | L3: Target not met
C4: 15-19 | D4: 20-24 | E4: 25-29 | F4: 30-34 | G4: 35-39 | H4: 40-44 | I4: 45-49
A6: Total | B6: No of women
B7: % interviewed
A9: Team
A10: Team 1 | B10: No of women
B11: % interviewed
A12: Team 2 | B12: No of women
B13: % interviewed
A14: Team 3 | B14: No of women
B15: % interviewed
A16: Team 4 | B16: No of women
B17: % interviewed
A18: Team 5 | B18: No of women
B19: % interviewed

Sheet F4M
A1: F4M. Age distribution of men interviewed
A2: Number of men age 15-49 years listed in the household schedule and proportion successfully interviewed by age group, according to interviewer team, Survey name, Year
C3: Men's age (15-49 years) | J3: Total | K3: Minimum percentage interviewed in any age group | L3: Target not met
C4: 15-19 | D4: 20-24 | E4: 25-29 | F4: 30-34 | G4: 35-39 | H4: 40-44 | I4: 45-49
A6: Total | B6: No of men
B7: % interviewed
A9: Team
A10: Team 1 | B10: No of men
B11: % interviewed
A12: Team 2 | B12: No of men
B13: % interviewed
A14: Team 3 | B14: No of men
B15: % interviewed
A16: Team 4 | B16: No of men
B17: % interviewed
A18: Team 5 | B18: No of men
B19: % interviewed

Sheet F5W
A1: F5W. Age displacement: women
A2: Number of women age 12-27 years listed in the household schedule by single year of age and age ratios 14/15 and 25/24, according to interviewer team, Survey name, Year
B3: Women's age (12 - 27 years) | R3: Total | S3: Age ratio (14/15) | T3: Target not met | U3: Age ratio (25/24) | V3: Target not met
B4: 12 | C4: 13 | D4: 14 | E4: 15 | F4: 16 | G4: 17 | H4: 18 | I4: 19 | J4: 20 | K4: 21 | L4: 22 | M4: 23 | N4: 24 | O4: 25 | P4: 26 | Q4: 27
A6: Total
A8: Team
A9: Team 1
A10: Team 2
A11: Team 3
A12: Team 4
A13: Team 5

Sheet F5M
A1: F5M. Age displacement: men
A2: Number of men age 12-27 years listed in the household schedules selected for the men's questionnaire by single year of age and age ratios 14/15 and 25/24, according to interviewer team, Survey name, Year
B3: Men's age (12 - 18 years) | R3: Total | S3: Age ratio (14/15) | T3: Target not met | U3: Age ratio (25/24) | V3: Target not met
B4: 12 | C4: 13 | D4: 14 | E4: 15 | F4: 16 | G4: 17 | H4: 18 | I4: 19 | J4: 20 | K4: 21 | L4: 22 | M4: 23 | N4: 24 | O4: 25 | P4: 26 | Q4: 27
A6: Total
A8: Team
A9: Team 1
A10: Team 2
A11: Team 3
A12: Team 4
A13: Team 5

Sheet F5UC
A1: F5UC. Age displacement: young children
A2: Number of children age 0-9 years listed in the household schedule by single year of age and age ratios 5/4 and 6/7, according to interviewer team, Survey name, Year
B3: Children's age (0 - 9 years) | L3: Total | M3: Age ratio (5/4) | N3: Target not met | O3: Age ratio (6/7) | P3: Target not met
B4: 0 | C4: 1 | D4: 2 | E4: 3 | F4: 4 | G4: 5 | H4: 6 | I4: 7 | J4: 8 | K4: 9
A6: Total
A8: Team
A9: Team 1
A10: Team 2
A11: Team 3
A12: Team 4
A13: Team 5

Sheet F6W
A1: F6W. Birth date reporting: Women
A2: Percent distribution of women age 15-49 years by completeness of date of birth/age reporting information, according to interviewer team, Survey name, Year
B3: Completeness of reporting | G3: Total | H3: Number of women | I3: Target not met
B4: Year and month of birth | C4: Year of birth and age | D4: Year of birth only | E4: Age only | F4: Other/No data
A7: Total | G7: 100
A9: Team
A10: Team 1 | G10: 100
A11: Team 2 | G11: 100
A12: Team 3 | G12: 100
A13: Team 4 | G13: 100
A14: Team 5 | G14: 100

Sheet F6W2
A1: F6W2. Birth date reporting: Women
A2: Percent distribution of women age 15-49 years by month of birth information, according to interviewer team, Survey name, Year
B3: Month of birth | M3: Total | N3: Number of women
B4: January | C4: February | D4: March | E4: April | F4: May | G4: June | H4: July | I4: August | J4: October | K4: November | L4: December
A6: Total | M6: 100
A8: Team
A9: Team 1 | M9: 100
A10: Team 2 | M10: 100
A11: Team 3 | M11: 100
A12: Team 4 | M12: 100
A13: Team 5 | M13: 100

Sheet F6M
A1: F6M. Birth date reporting: Men
A2: Percent distribution of men age 15-49 years by completeness of date of birth/age reporting information, according to interviewer team, Survey name, Year
B3: Completeness of reporting | G3: Total | H3: Number of men | I3: Target not met
B4: Year and month of birth | C4: Year of birth and age | D4: Year of birth only | E4: Age only | F4: Other/No data
A7: Total | G7: 100
A9: Team
A10: Team 1 | G10: 100
A11: Team 2 | G11: 100
A12: Team 3 | G12: 100
A13: Team 4 | G13: 100
A14: Team 5 | G14: 100

Sheet F6U
A1: F6U. Birth date reporting: Children under-5
A2: Percent distribution of children age under-5 years by completeness of date of birth/age reporting information, according to interviewer team, Survey name, Year
B3: Completeness of reporting | G3: Total | H3: Number of children under-5 | I3: Target not met
B4: Year and month of birth | C4: Year of birth and age | D4: Year of birth only | E4: Age only | F4: Other/No data
A7: Total | G7: 100
A9: Team
A10: Team 1 | G10: 100
A11: Team 2 | G11: 100
A12: Team 3 | G12: 100
A13: Team 4 | G13: 100
A14: Team 5 | G14: 100

Sheet F6C
A1: F6C. Birth date reporting: Children, adolescents and young people
A2: Percent distribution of children, adolescents and young people age 5-24 years by completeness of date of birth/age reporting information, according to interviewer team, Survey name, Year
B3: Completeness of reporting | G3: Total | H3: Number of children, adolescents and young people | I3: Target not met
B4: Year and month of birth | C4: Year of birth and age | D4: Year of birth only | E4: Age only | F4: Other/No data
A7: Total | G7: 100
A9: Team
A10: Team 1 | G10: 100
A11: Team 2 | G11: 100
A12: Team 3 | G12: 100
A13: Team 4 | G13: 100
A14: Team 5 | G14: 100

Sheet F6B
A1: F6B. Birth date reporting: First and last births
A2: Percent distribution of first and last births to women age 15-49 years by completeness of date of birth, according to interviewer team, Survey name, Year
B3: Completeness of reporting
B4: Date of first birth | F4: Number of first births | G4: Total | H4: Target not met | J4: Date of last birth | M4: Number of last births | N4: Total | O4: Target not met
B5: Both month and year | C5: Year only | D5: Completed years since first birth only | E5: Other/No data | J5: Both month and year | K5: Year only | L5: Other/No data
A7: Total | G7: 100 | N7: 100
A9: Team
A10: Team 1 | G10: 100 | N10: 100
A11: Team 2 | G11: 100 | N11: 100
A12: Team 3 | G12: 100 | N12: 100
A13: Team 4 | G13: 100 | N13: 100
A14: Team 5 | G14: 100 | N14: 100

Sheet F7W
A1: F7W. Question responses by team: Women's questionnaire
A2: Percentage of certain responses to key questions in the women's questionnaires, according to interviewer team, Survey name, Year
B3: Percentage of women: | F3: Number of women
B4: With a live birth in the last 2 years | C4: Currently pregnant | D4: Who have ever heard of FGM | E4: Who have ever had sex
A6: Total
A8: Team
A9: Team 1
A10: Team 2
A11: Team 3
A12: Team 4
A13: Team 5
A15: Note: Columns in blue can only be produced if associated topics have been included in the Questionnaire for Women

Sheet F7M
A1: F7M. Question responses by team: Men's questionnaire
A2: Percentage of certain responses to key questions in the men's questionnaires, according to interviewer team, Survey name, Year
B3: Ever had sex | C3: Number of men
A5: Total
A7: Team
A8: Team 1
A9: Team 2
A10: Team 3
A11: Team 4
A12: Team 5
A14: Note: Columns in blue can only be produced if associated topics have been included in the Questionnaire for Men

Sheet F7U
A1: F7U. Question responses by team: Under-5 questionnaire
A2: Percentage of certain responses to key questions in the under five questionnaire, according to interviewer team, Survey name, Year
B3: Percentage of children with: | E3: Number of children under 5 | F3: Percentage of children with all "No" responses to Child Discipline | G3: Number of children age 1-4 | H3: Percentage of children with all "No difficulty" responses to Child Functioning | I3: Number of children age 2-4 | J3: Percentage of children with: | M3: Number of children age 6-23 months
B4: Diarrhea in the last 2 weeks | C4: A symptom of ARI in the last 2 weeks | D4: Fever in the last 2 weeks | J4: All "No" or "DK" responses to BD7 liquids | K4: All "No" or "DK" responses to BD8 solid or semi-solid foods | L4: Zero number of times food and no breastmilk
A6: Total
A8: Team
A9: Team 1
A10: Team 2
A11: Team 3
A12: Team 4
A13: Team 5
A15: Note: Columns in blue can only be produced if associated topics have been included in the Questionnaire for Children U5

Sheet F7C
A1: F7C. Question responses by team: 5-17 questionnaire
A2: Percentage of certain responses to key questions in the 5-17 questionnaire, according to interviewer team, Survey name, Year
B3: Percentage of children with all "No" responses to Child Discipline | C3: Number of children age 5-14 | D3: Percentage of children with all "No difficulty" responses to Child Functioning | E3: Number of children age 5-17
A6: Total
A8: Team
A9: Team 1
A10: Team 2
A11: Team 3
A12: Team 4
A13: Team 5
A15: Note: Columns in blue can only be produced if associated topics have been included in the Questionnaire for Children & Adolescents Age 5-17

Sheet F8A
A1: F8A: Observation of birth certificates
A2: Percentage of children under 5 who have a birth certificate, percentage of children under 5 whose birth certificate was seen by the interviewer, percentage of children whose birth has been registered, and proportion of birth certificates seen, according to interviewer team, Survey name, Year
B3: Percent of children reported to have a birth certificate | C3: Percent of children whose birth certificate was seen by interviewer | D3: Percent of children whose birth was registered but does not have a birth certificate | E3: Percent of all births with a birth certificate or registered | F3: Number of children | G3: Proportion of birth certificates seen (%) | H3: Target not met
B4: (1) | C4: (2) | D4: (3) | E4: (4) | F4: (5) | G4: (6)=(2)/(1)
A6: Total
A8: Team
A9: Team 1
A10: Team 2
A11: Team 3
A12: Team 4
A13: Team 5
A15: Note: This table can only be produced if the Birth Registration topic is included in the survey

Sheet F8B
A1: F8B. Observation of vaccination cards
A2: Percentage of children under age 3 who have a vaccination card, percentage of children whose card was seen by the interviewer, and proportion of cards seen, according to interviewer team, Survey name, Year
B3: Percent of children reported to have a vaccination card | C3: Percent of children whose vaccination card was seen by interviewer | D3: Number of children | E3: Proportion of cards seen (%) | F3: Target not met
B4: (1) | C4: (2) | D4: (3) | E4: (4)=(2)/(1)
A6: Total
A8: Team
A9: Team 1
A10: Team 2
A11: Team 3
A12: Team 4
A13: Team 5

Sheet F8C
A1: F8C. Observation of women's health cards
A2: Percentage of women with a live birth in the last 2 years who have a health card, whether the health card was seen by the interviewer, and proportion of health cards seen, according to interviewer team, Survey name, Year
B3: Percent of women who have a health card | C3: Percent of women whose health card was seen by interviewer | D3: Number of women with a live birth in the last 2 years | E3: Proportion of health cards seen (%) | F3: Target not met
B4: (1) | C4: (2) | D4: (3) | E4: (4)=(2)/(1)
A6: Total
A8: Team
A9: Team 1
A10: Team 2
A11: Team 3
A12: Team 4
A13: Team 5

Sheet F8D
A1: F8D. Observation of bednets
A2: Percentage of bednets observed by the interviewer in all interviewed households, according to interviewer team, Survey name, Year
B3: Percent of bednets observed by interviewer | C3: Total number of bednets | D3: Target not met | E3: Percent of households with at least one bednet | F3: Number of households
A5: Total
A7: Team
A8: Team 1
A9: Team 2
A10: Team 3
A11: Team 4
A12: Team 5
A14: Note: This table can only be produced if the ITN module of the Malaria topic is included in the survey

Sheet F8E
A1: F8E. Observation of places for hand washing
A2: Percentage of places for handwashing observed by the interviewer in all interviewed households, according to interviewer team, Survey name, Year
B3: Percent of households where place for handwashing was observed | C3: Place for handwashing not in the dwelling, plot or yard | D3: No permission to see place for handwashing | E3: Other | F3: Number of households | G3: Target not met
A5: Total
A7: Team
A8: Team 1
A9: Team 2
A10: Team 3
A11: Team 4
A12: Team 5

Sheet F8Q
A1: F8Q. Observation and collection of water quality samples
A2: Percentage of observed sources of household water quality sample, collected source samples and number of blank test results with E. coli detected, according to interviewer team, Survey name, Year
B3: Household sample | E3: Source sample | H3: Number of households selected for water quality testing | I3: Blank test: | L3: Number of households selected for blank testing
B4: Source observed | C4: Unable to observe source | E4: Shown | G4: Not shown | I4: Number of blank tests with E. coli: | K4: Test not conducted
E5: Collected | F5: Not collected | I5: Detected | J5: Not detected
A7: Total
A9: Team
A10: Team 1
A11: Team 2
A12: Team 3
A13: Team 4
A14: Team 5

Sheet F9A
A1: F9A. Height and weight of children (age 0-4)
A2: Percent distribution of children under 5 by result of height and weight measurement, and percentage of children measured who have out of range values, interference, or incomplete date of birth, according to interviewer team, Survey name, Year
B3: Result of height and weight measurement | G3: Total | H3: Number of children age 0-4 years | I3: Among children measured
B4: Either or both measured | C4: Child not present | D4: Child or mother/ caretaker refused | E4: Other | F4: Missing | I4: Height out of range (%) | J4: Hair interference (%) | K4: Weight out of range (%) | L4: Clothing interference (%) | M4: Date of birth incomplete (%)
A6: Total | G6: 100
A8: Team
A9: Team 1 | G9: 100
A10: Team 2 | G10: 100
A11: Team 3 | G11: 100
A12: Team 4 | G12: 100
A13: Team 5 | G13: 100

Sheet F9B
A1: F9B. Heaping in anthropometric measurements (age 0-4)
A2: Percentage of weight and height/length measurements by digits reported with 0 and 5 among measured children age 0-4 years, Survey name, Year
B3: Weight measurements | E3: Target not met | F3: Number of children age 0-4 years with weight measurement | G3: Sum of all absolute differences from 10 per cent, from 0 to 9 | H3: Height measurements | K3: Target not met | L3: Number of children age 0-4 years with height measurement | M3: Sum of all absolute differences from 10 per cent, from 0 to 9
B4: Percent reported with digit | D4: Heaping ratio | H4: Percent reported with digit | J4: Heaping ratio
B5: 0 | C5: 5 | H5: 0 | I5: 5
B6: (1) | C6: (2) | D6: (3)=((2)+(1))/20 | H6: (1) | I6: (2) | J6: (3)=((2)+(1))/20
A8: Total
A10: Team
A11: Team 1
A12: Team 2
A13: Team 3
A14: Team 4
A15: Team 5

Sheet F9C
A1: F9C. Height and weight of children (age 5-9)
A2: Percent distribution of children age 5-9 years by result of height and weight measurement, and percentage of children measured who have out of range values, interference, or incomplete date of birth, according to interviewer team, Survey name, Year
B3: Result of height and weight measurement | G3: Total | H3: Number of children age 5-9 years | I3: Among children measured
B4: Either or both measured | C4: Child not present | D4: Child or mother/ caretaker refused | E4: Other | F4: Missing | I4: Height out of range (%) | J4: Hair interference (%) | K4: Weight out of range (%) | L4: Clothing interference (%) | M4: Date of birth incomplete (%)
A6: Total | G6: 100
A8: Team
A9: Team 1 | G9: 100
A10: Team 2 | G10: 100
A11: Team 3 | G11: 100
A12: Team 4 | G12: 100
A13: Team 5 | G13: 100
A15: Note: This table can only be produced if the Anthropometric Measurements of children age 5-9 years topic is included in the survey

Sheet F9D
A1: F9D. Heaping in anthropometric measurements (age 5-9)
A2: Percentage of weight and height/length measurements by digits reported with 0 and 5 among measured children age 5-9 years, Survey name, Year
B3: Weight measurements | E3: Target not met | F3: Number of children age 5-9 years with weight measurement | G3: Sum of all absolute differences from 10 per cent, from 0 to 9 | H3: Height measurements | K3: Target not met | L3: Number of children age 5-9 years with height measurement | M3: Sum of all absolute differences from 10 per cent, from 0 to 9
B4: Percent reported with digit | D4: Heaping ratio | H4: Percent reported with digit | J4: Heaping ratio
B5: 0 | C5: 5 | H5: 0 | I5: 5
B6: (1) | C6: (2) | D6: (3)=((2)+(1))/20 | H6: (1) | I6: (2) | J6: (3)=((2)+(1))/20
A8: Total
A10: Team
A11: Team 1
A12: Team 2
A13: Team 3
A14: Team 4
A15: Team 5
A17: Note: This table can only be produced if the Anthropometric Measurements of children age 5-9 years topic is included in the survey

Sheet F10
A1: F10. Children ever born and children surviving
A2: Number of women with a completed interview, total number of children ever born (CEB), and mean number of CEB, according to interviewer team, Survey name, Year
B3: Number of all women with a completed interview | C3: Total number of living children | D3: Mean number of living children | E3: Total number of deceased children | F3: Mean number of deceased children | G3: Total number of children ever born | H3: Mean number of children ever born | I3: Target not met
B4: (1) | C4: (2) | D4: (3)=(2)/(1) | E4: (4) | F4: (5)=(4)/(1) | G4: (6) | H4: (7)=(6)/(1)
A6: Total
A8: Team
A9: Team 1
A10: Team 2
A11: Team 3
A12: Team 4
A13: Team 5

Sheet F10B
A1: F10B: Fertility rates
A2: Adolescent birth rate, age-specific and total fertility rates, the general fertility rate, and the crude birth rate for the three-year period preceding the survey, by area of residence, Survey name, Year
B3: Urban | C3: Rural | D3: Total
A5: AgeA
A6: 15-19
A7: 20-24
A8: 25-29
A9: 30-34
A10: 35-39
A11: 40-44
A12: 45-49
A14: TFR (15-49 years)B
A15: GFRC
A16: CBRD
A17: A The age-specific fertility rates (ASFR) are the number of live births in the last 3 years, divided by the average number of women in that age group during the same period, expressed per 1,000 women. The age-specific fertility rate for women age 15-19 years is also termed as the adolescent birth rate
... A22: Rates are calculated for the three-year (1-36 months) period preceding the survey, based on data collected in birth histories. The month of interview is ignored, as it would represent a censored (incomplete) period of observation. See notes below TM.2.1 for further details.

Sheet F11A
A1: F11B. Birth histories: Birth date reporting for living children
A2: Percent distribution of living children by completeness of date of birth/age information in birth histories, according to interviewer team, Survey name, Year
B3: Completeness of reporting | G3: Total | H3: Number of living children | I3: Target not met
B4: Year and month of birth | C4: Year of birth and age | D4: Year of birth only | E4: Age only | F4: Other/No data
A7: Total | G7: 100
A9: Team
A10: Team 1 | G10: 100
A11: Team 2 | G11: 100
A12: Team 3 | G12: 100
A13: Team 4 | G13: 100
A14: Team 5 | G14: 100

Sheet F11B
A1: F11C. Birth histories: Birth date reporting for deceased children
A2: Percent distribution of deceased children by completeness of date of birth information in birth histories, according to interviewer team, Survey name, Year
B3: Completeness of reporting | F3: Total | G3: Number of deceased children | H3: Target not met
B4: Year and month of birth | C4: Year of birth only | D4: Month of birth only | E4: No data
A6: Total | F6: 100
A8: Team
A9: Team 1 | F9: 100
A10: Team 2 | F10: 100
A11: Team 3 | F11: 100
A12: Team 4 | F12: 100
A13: Team 5 | F13: 100

Sheet F11C
A1: F11A. Birth histories: Birth displacement
A2: Number of births since 2011 by year of birth in birth histories, according to interviewer team, Survey name, Year
B3: Year of birth | P3: Total
B4: 2011 | C4: 2012 | D4: 2013 | E4: 2014 | F4: 2015 | G4: 2016 | H4: 2017 | I4: 2018 | J4: 2019 | K4: 2020 | L4: 2021 | M4: 2022 | N4: 2023 | O4: Missing
A6: Total
A8: Team
A9: Team 1
A10: Team 2
A11: Team 3
A12: Team 4
A13: Team 5

Sheet F11D
A1: F11D. Birth histories: Age at death heaping
A2: Number of deaths in the last 15 years by reported months of age at death (including age at death reported as "one year") and the 12 months ratios, according to interviewer team, Survey name, Year
B3: Age at death (in months) | L3: Total 8-16 months (including "1 year") | M3: 12 months ratio (including "1 year") | N3: Target not met
B4: 8 m. | C4: 9 m. | D4: 10 m. | E4: 11 m. | F4: 12 months | H4: 13 m. | I4: 14 m. | J4: 15 m. | K4: 16 m.
F5: 12 m. | G5: Reported as "1 year"
A7: Total
A9: Team
A10: Team 1
A11: Team 2
A12: Team 3
A13: Team 4
A14: Team 5

Sheet F11E
A1: F11E. Birth histories: Child mortality
A2: Number of births in the last 15 years by survival status and age at death (for those who died), the ratio of neonatal deaths (<1 month) to all infant deaths (<12 months), and the ratio of infant deaths to all births, according to interviewer team, Survey name, Year
B3: Age at death in months for children who died | G3: Still alive | H3: Total births | I3: Ratio of neonatal to infant | J3: Infant deaths to total births (per thousand)
B4: < 1 month | C4: 1-11 months | D4: 12+ months | E4: Missing | F4: Total dead
B5: (1) | C5: (2) | D5: (3) | E5: (4) | F5: (5)=(1+2+3+4) | G5: (6) | H5: (7)=(5+6) | I5: (1)/(1+2) | J5: (1+2)/(7)
A7: Total
A9: Team
A10: Team 1
A11: Team 2
A12: Team 3
A13: Team 4
A14: Team 5

Sheet F12
A1: F12. Maternal mortality
A2: Number of deceased sisters and number and percentage for whom age at death is missing; number of sisters who died at age 12 years and above and number and percentage for whom information on death during pregnancy, during delivery or after delivery is missing, and for whom information on timing of death ("years ago") is missing, according to interviewer team, Survey name, Year
A3: Team | B3: Mean number of siblings | C3: All deceased sisters | F3: Target not met in Column (3) | G3: Sisters who died at age 12+ | J3: Target not met in Column (6) | K3: Sisters who died at age 12+
C4: Number | D4: Missing age at death | G4: Number | H4: Missing information on death during pregnancy & during delivery & after delivery | K4: Missing information on "years ago" of death | M4: Target not met in Column (8)
D5: Number | E5: % | H5: Number | I5: % | K5: Number | L5: %
C6: (1) | D6: (2) | E6: (3)=(2/1) | G6: (4) | H6: (5) | I6: (6)=5/4) | K6: (7) | L6: (8)=(7/4)
A8: Total
A10: Team
A11: Team 1
A12: Team 2
A13: Team 3
A14: Team 4
A15: Team 5
A17: Note: This table can only be produced if the Maternal Mortality topic is included in the survey

Sheet F13A
A1: F13A. Mental Health module: Privacy
A2: Percentage of women and men (age 15-24) who were not administered Mental Health module because privacy was not possible, and percentage to whom the suicide questions were not administered because privacy was not possible, by interviewer team, Survey name, Year
B3: Women (age 15-24) | F3: Men (age 15-24)
B4: Percentage of women (age 15-24) to whom the mental health module was not administered due to lack of privacy | C4: Percentage of women (age 15-24) to whom the suicide questions in mental health module were not administered due to lack of privacy** | D4: Number of women (age 15-24) | F4: Percentage of men (age 15-24) to whom the mental health module was not administered due to lack of privacy* | G4: Percentage of men (age 15-24) to whom the suicide questions in mental health module were not administered due to lack of privacy** | H4: Number of men (age 15-24)
A6: Total
A8: Team
A9: Team 1
A10: Team 2
A11: Team 3
A12: Team 4
A13: Team 5
B14: MH1=2 | C14: MH40=2 | F14: MMH1=2 | G14: MMH40=2
A15: Note: This table can only be produced if the Mental Health topic is included in the survey

Sheet F13B
A1: F13B. Violence Against Women module: Privacy
A2: Percentage of women selected for Violence Against Women module where the module was not administered because privacy was not possible, by interviewer team, Survey name, Year
B3: Percentage of women selected for Violence Against Women module where the module was not administered due to lack of privacy | C3: Number of women selected for Violence Against Women module
A5: Total
A7: Team
A8: Team 1
A9: Team 2
A10: Team 3
A11: Team 4
A12: Team 5
B13: VW1=2
A14: Note: This table can only be produced if the Violence Against Women topic is included in the survey

Sheet F14
A1: F14. Food Insecurity
A2: Percentage of households with certain responses to questions in Food Insecurity Expereince module, Survey name, Year
B3: Percentage with all: | D3: Number of households
B4: "Missing" responses to all FIES questions | C4: "No" responses to all FIES questions
A6: Total
A8: Team
A9: Team 1
A10: Team 2
A11: Team 3
A12: Team 4
A13: Team 5
A14: Note: This table can only be produced if the Food Insecurity Experience is included in the survey

Sheet F20
A1: F20. Phone ownership and provision of consent and phone numbers for MICS Plus survey
A2: Percentage of households by ownership of fixed telephone line or mobile telephone and percentage of households with at least one consent given and one phone number provided for MICS Plus survey, Survey name, Year
B3: Percentage with: | F3: Percentage with: | H3: Number of completed households
B4: A fixed telephone line | C4: Any member with a mobile telephone | D4: Either a fixed telephone line or any member with a mobile telephone | F4: At least one consent given for MICS Plus survey | G4: At least one phone number provided for MICS Plus survey
A6: Total
A8: Team
A9: Team 1
A10: Team 2
A11: Team 3
A12: Team 4
A13: Team 5
A14: Phone ownership (according to respondent to HH questionnaire)
A15: Yes
A16: No
A17: Note: This table can only be produced if the MICS Plus Consent questions are included in the survey
